<?xml version="1.0" encoding="utf-8"?>
<!-- This URDF was automatically created by SolidWorks to URDF Exporter! Originally created by Stephen Brawner (brawner@gmail.com) 
     Commit Version: 1.6.0-4-g7f85cfe  Build Version: 1.6.7995.38578
     For more information, please see http://wiki.ros.org/sw_urdf_exporter -->
<robot xmlns:xacro="http://www.ros.org/wiki/xacro" name="piper_l_camera">

<xacro:include filename="$(find realsense2_description)/urdf/test_d435_camera.urdf.xacro" />

  <link
    name="base_link">
    <inertial>
      <origin xyz="-0.00347 -0.00012 0.04283" rpy="0 0 0"/>
      <mass value="1.07"/>
      <inertia 
          ixx="0.00099887" 
          ixy="0.00000194" 
          ixz="0.00000613" 
          iyy="0.00112771" 
          iyz="0.00000201" 
          izz="0.00096552" />
    </inertial>
    <visual>
      <origin
        xyz="0 0 0"
        rpy="0 0 0" />
      <geometry>
        <mesh
          filename="package://piper_h_description/meshes/dae/base_link.dae" />
      </geometry>
      <material
        name="">
        <color
          rgba="1 1 1 1" />
      </material>
    </visual>
    <collision>
      <origin
        xyz="0 0 0"
        rpy="0 0 0" />
      <geometry>
        <mesh
          filename="package://piper_h_description/meshes/dae/base_link.dae" />
      </geometry>
    </collision>
  </link>
  <link
    name="link1">
    <inertial>
      <origin xyz="0.00038 -0.00039 -0.00317" rpy="0 0 0"/>
      <mass value="0.71"/>
      <inertia 
          ixx="0.00049803" 
          ixy="0.00000022" 
          ixz="0.00000810" 
          iyy="0.00040527" 
          iyz="0.00000116" 
          izz="0.00045753" />
    </inertial>
    <visual>
      <origin
        xyz="0 0 0"
        rpy="0 0 0" />
      <geometry>
        <mesh
          filename="package://piper_h_description/meshes/dae/link1.dae" />
      </geometry>
      <material
        name="">
        <color
          rgba="1 1 1 1" />
      </material>
    </visual>
    <collision>
      <origin
        xyz="0 0 0"
        rpy="0 0 0" />
      <geometry>
        <mesh
          filename="package://piper_h_description/meshes/dae/link1.dae" />
      </geometry>
    </collision>
  </link>
  <joint
    name="joint1"
    type="revolute">
    <origin
      xyz="0 0 0.123"
      rpy="0 0 0" />
    <parent
      link="base_link" />
    <child
      link="link1" />
    <axis
      xyz="0 0 1" />
    <limit lower="-2.618" upper="2.618" effort="100" velocity="3" />
  </joint>
  <link
    name="link2">
    <inertial>
      <origin xyz="0.21849 -0.00875 0.00126" rpy="0 0 0"/>
      <mass value="1.16"/>
      <inertia 
          ixx="0.00103112" 
          ixy="0.00035994" 
          ixz="0.00012698" 
          iyy="0.01204356" 
          iyz="0.00000492" 
          izz="0.01188565" />
    </inertial>
    <visual>
      <origin
        xyz="0 0 0"
        rpy="0 0 0" />
      <geometry>
        <mesh
          filename="package://piper_h_description/meshes/dae/link2.dae" />
      </geometry>
      <material
        name="">
        <color
          rgba="1 1 1 1" />
      </material>
    </visual>
    <collision>
      <origin
        xyz="0 0 0"
        rpy="0 0 0" />
      <geometry>
        <mesh
          filename="package://piper_h_description/meshes/dae/link2.dae" />
      </geometry>
    </collision>
  </link>
  <joint
    name="joint2"
    type="revolute">
    <origin
      xyz="0 0 0"
      rpy="1.5708 -0.13674 3.1416" />
    <parent
      link="link1" />
    <child
      link="link2" />
    <axis
      xyz="0 0 1" />
    <limit lower="0" upper="3.14" effort="100" velocity="3" />
  </joint>
  <link
    name="link3">
    <inertial>
      <origin xyz="-0.00778 -0.14512 -0.00047" rpy="0 0 0"/>
      <mass value="0.55"/>
      <inertia 
          ixx="0.00285399" 
          ixy="0.00008683" 
          ixz="0.00000260" 
          iyy="0.00025517" 
          iyz="0.00004073" 
          izz="0.00280819" />
    </inertial>
    <visual>
      <origin
        xyz="0 0 0"
        rpy="0 0 0" />
      <geometry>
        <mesh
          filename="package://piper_h_description/meshes/dae/link3.dae" />
      </geometry>
      <material
        name="">
        <color
          rgba="1 1 1 1" />
      </material>
    </visual>
    <collision>
      <origin
        xyz="0 0 0"
        rpy="0 0 0" />
      <geometry>
        <mesh
          filename="package://piper_h_description/meshes/dae/link3.dae" />
      </geometry>
    </collision>
  </link>
  <joint
    name="joint3"
    type="revolute">
    <origin
      xyz="0.28508 0 0"
      rpy="0 0 -1.8796" />
    <parent
      link="link2" />
    <child
      link="link3" />
    <axis
      xyz="0 0 1" />
    <limit lower="-2.697" upper="0" effort="100" velocity="3" />
  </joint>
  <link
    name="link4">
    <inertial>
      <origin xyz="0.00051 -0.00091 -0.00395" rpy="0 0 0"/>
      <mass value="0.36"/>
      <inertia 
        ixx="0.00018477" 
        ixy="0.00000115" 
        ixz="0.00000323" 
        iyy="0.00016906" 
        iyz="0.00000674" 
        izz="0.00015871" />
    </inertial>
    <visual>
      <origin
        xyz="0 0 0"
        rpy="0 0 0" />
      <geometry>
        <mesh
          filename="package://piper_h_description/meshes/dae/link4.dae" />
      </geometry>
      <material
        name="">
        <color
          rgba="1 1 1 1" />
      </material>
    </visual>
    <collision>
      <origin
        xyz="0 0 0"
        rpy="0 0 0" />
      <geometry>
        <mesh
          filename="package://piper_h_description/meshes/dae/link4.dae" />
      </geometry>
    </collision>
  </link>
  <joint
    name="joint4"
    type="revolute">
    <origin
      xyz="0 -0.25666 0"
      rpy="1.5708 0 0.17203" />
    <parent
      link="link3" />
    <child
      link="link4" />
    <axis
      xyz="0 0 1" />
    <limit lower="-1.832" upper="1.832" effort="100" velocity="3" />
  </joint>
  <link
    name="link5">
    <inertial>
      <origin xyz="0.00015 -0.06349 -0.00253" rpy="0 0 0"/>
      <mass value="0.38"/>
      <inertia 
        ixx="0.00030399" 
        ixy="0.00000167" 
        ixz="0.00000011" 
        iyy="0.00016834" 
        iyz="0.00004817" 
        izz="0.00029057" />
    </inertial>
    <visual>
      <origin
        xyz="0 0 0"
        rpy="0 0 0" />
      <geometry>
        <mesh
          filename="package://piper_h_description/meshes/dae/link5.dae" />
      </geometry>
      <material
        name="">
        <color
          rgba="1 1 1 1" />
      </material>
    </visual>
    <collision>
      <origin
        xyz="0 0 0"
        rpy="0 0 0" />
      <geometry>
        <mesh
          filename="package://piper_h_description/meshes/dae/link5.dae" />
      </geometry>
    </collision>
  </link>
  <joint
    name="joint5"
    type="revolute">
    <origin
      xyz="0 0 0"
      rpy="-1.5708 -0.087272 0" />
    <parent
      link="link4" />
    <child
      link="link5" />
    <axis
      xyz="0 0 -1" />
    <limit lower="-1.22" upper="1.22" effort="100" velocity="3" />
  </joint>
  <link
    name="link6">
    <inertial>
      <origin xyz="0 0 -0.00351" rpy="0 0 0"/>
      <mass value="0.01"/>
      <inertia
        ixx="0.00000064"
        ixy="0"
        ixz="0"
        iyy="0.00000064"
        iyz="0"
        izz="0.00000106"/>
    </inertial>
    <visual>
      <origin
        xyz="0.008 -0.002 0.064"
        rpy="-1.57 0 1.57" />
      <geometry>
        <mesh
          filename="package://piper_h_description/meshes/dae/gripper_base_100_v3.dae" />
      </geometry>
      <material
        name="">
        <color
          rgba="1 1 1 1" />
      </material>
    </visual>
    <collision>
      <origin
        xyz="0.008 -0.002 0.064"
        rpy="-1.57 0 1.57" />
      <geometry>
        <mesh
          filename="package://piper_h_description/meshes/dae/gripper_base_100_v3.dae" />
      </geometry>
    </collision>
  </link>
  <joint
    name="joint6"
    type="revolute">
    <origin
      xyz="0 -0.1 0"
      rpy="1.5708 0 0.0" />
    <parent
      link="link5" />
    <child
      link="link6" />
    <axis
      xyz="0 0 1" />
    <limit lower="-3.14" upper="3.14" effort="100" velocity="3" />

  </joint>

<link name="link7">
  <visual>
    <inertial>
      <origin rpy="0 0 0" xyz="0.000277816920932317 -0.0467673824063769 -0.00921030054508036"/>
      <mass value="0.0264822021416248"/>
      <inertia ixx="9.99779119357223E-06" ixy="-1.57542283433504E-07" ixz="2.71367446701359E-08" iyy="6.17952441557932E-06" iyz="1.58939319453383E-06" izz="1.4210192754512E-05"/>
    </inertial>
    <geometry>
      <mesh filename="package://piper_h_description/meshes/dae/link7.dae" />
    </geometry>
    <material name="LightGrey">
      <color rgba="0.7 0.7 0.7 1.0"/>
    </material>
  </visual>
  <collision>
    <geometry>
      <mesh filename="package://piper_h_description/meshes/dae/link7.dae" />
    </geometry>
  </collision>
</link>
    <joint name="joint7" type="prismatic">
        <origin xyz="0 0 0.13503" rpy="1.5708 0 0" />
        <parent link="link6" />
        <child link="link7" />
        <axis xyz="0 0 -1" />
        <limit lower="0" upper="0.05" effort="100" velocity="1" />
    </joint>

    <link name="link8">
        <inertial>
        <origin
            xyz="0.000277816920932317 0.0467673824063769 -0.00921030054508036"
            rpy="0 0 0" />
        <mass value="0.0264822021416248" />
        <inertia
            ixx="9.99779119357223E-06"
            ixy="-1.57542283433504E-07"
            ixz="2.71367446701359E-08"
            iyy="6.17952441557932E-06"
            iyz="1.58939319453383E-06"
            izz="1.4210192754512E-05" />
        </inertial>
        <visual>
        <origin xyz="0 0 0" rpy="0 0 0" />
        <geometry>
          <mesh filename="package://piper_h_description/meshes/dae/link8.dae" />
        </geometry>
        <material name="">
            <color rgba="0.792156862745098 0.819607843137255 0.933333333333333 1" />
        </material>
        </visual>
        <collision>
        <origin xyz="0 0 0" rpy="0 0 0" />
        <geometry>
          <mesh filename="package://piper_h_description/meshes/dae/link8.dae" />
        </geometry>
        </collision>
    </link>
    <joint name="joint8" type="prismatic">
        <origin xyz="0 0 0.13503" rpy="-1.5708 0 0" />
        <parent link="link6" />
        <child link="link8" />
        <axis xyz="0 0 1" />
        <limit lower="-0.05" upper="0" effort="100" velocity="1" />
    </joint>

    <link name="camera_stand_link">
        <inertial>
            <origin xyz="0.0 0.0 0.0" rpy="0.0 0.0 0.0"/>
            <mass value="0.0"/>
            <inertia ixx="0.0" ixy="0.0" ixz="0.0" iyy="0.0" iyz="0.0" izz="0.0"/>
        </inertial>
        <visual name="">
            <origin xyz="0.0 0.0 0.0" rpy="0.0 3.14 1.57"/>
            <geometry>
                <mesh filename="package://piper_h_description/meshes/dae/realsense_mid_stand_v2.dae" />
            </geometry>
        </visual>
        <collision>
            <origin xyz="0.0 0.0 0.0" rpy="0.0 3.14 1.57"/>
            <geometry>
                <mesh filename="package://piper_h_description/meshes/dae/realsense_mid_stand_v2.dae" />
            </geometry>
        </collision>
    </link>
    <joint name="camera_stand_joint" type="fixed">
        <origin xyz="-0.034 -0.002 0.023" rpy="0 0 0"/>
        <parent link="link6"/>
        <child link="camera_stand_link"/>
        <axis xyz="0.0 0.0 0.0"/>
        <limit lower="0.0" upper="0.0" effort="0.0" velocity="0.0"/>
    </joint>

    <joint name="d435_camera_joint" type="fixed">
        <origin xyz="-0.032 -0.028 0.0" rpy="0.0 -1.22 0"/>
        <parent link="camera_stand_link"/>
        <child link="d435_camera_link"/>
        <axis xyz="0.0 0.0 0.0"/>
        <limit lower="0.0" upper="0.0" effort="0.0" velocity="0.0"/>
    </joint>


</robot>